Workbook

Sheet Raw Data
A1: Oyster Reef Restoration — Raw Data
A2: 75 samples; source file: oyster_latlong_elevation_tex_element.csv
A4: sampleID | B4: treatment | C4: treatment substrate | D4: substrate sampled | E4: density (#/m^2) | F4: percent cover | G4: easting | H4: northing | I4: elevation (m NAVD) | J4: longitude | K4: latitude | L4: mean oyster density (#/m^2) | M4: wt %N | N4: wt %total C | O4: %CaCO3 | P4: %TIC | Q4: wt %TOC by difference | R4: C:N ratio | S4: fraction > 6mm | T4: fraction 2-6mm | U4: fraction .063-2mm | V4: fraction <0.063mm
A5: T01 Q1 | B5: h | C5: jute | D5: jute | E5: 2176 | F5: 100 | G5: 102949.59 | H5: 535503.48 | I5: -0.207 | J5: -82.997614 | K5: 29.162967 | L5: 1116.8
A6: T01 Q2 | B6: h | C6: jute | D6: shell | E6: 0 | F6: 0 | G6: 102952.85 | H6: 535507.08 | I6: -0.287 | J6: -82.997581 | K6: 29.162999 | L6: 1116.8 | M6: 0.25 | N6: 10.27 | O6: 73.1 | P6: 8.77 | Q6: 1.5 | R6: 6 | S6: 0.37 | T6: 0.17 | U6: 0.23 | V6: 0.23
A7: T01 Q3 | B7: h | C7: jute | D7: shell | E7: 16 | F7: 1 | G7: 102948.15 | H7: 535502.9 | I7: -0.279 | J7: -82.997628 | K7: 29.162961 | L7: 1116.8 | M7: 0.21 | N7: 10.16 | O7: 72.63 | P7: 8.72 | Q7: 1.44 | R7: 6.9 | S7: 0.44 | T7: 0.13 | U7: 0.22 | V7: 0.2
A8: T01 Q4 | B8: h | C8: jute | D8: jute | E8: 1744 | F8: 100 | G8: 102947.12 | H8: 535502.23 | I8: -0.178 | J8: -82.997639 | K8: 29.162955 | L8: 1116.8
A9: T01 Q5 | B9: h | C9: jute | D9: jute | E9: 1648 | F9: 100 | G9: 102951.72 | H9: 535506.3 | I9: -0.19 | J9: -82.997592 | K9: 29.162992 | L9: 1116.8
A10: T02 Q1 | B10: c | C10: shell | D10: shell | E10: 0 | F10: 0 | G10: 102958.09 | H10: 535510.26 | I10: -0.317 | J10: -82.997527 | K10: 29.163028 | L10: 0 | M10: 0.26 | N10: 10.19 | O10: 68.11 | P10: 8.17 | Q10: 2.02 | R10: 7.8 | S10: 0.34 | T10: 0.09 | U10: 0.26 | V10: 0.31
A11: T02 Q2 | B11: c | C11: shell | D11: shell | E11: 0 | F11: 0 | G11: 102959.32 | H11: 535510.87 | I11: -0.313 | J11: -82.997514 | K11: 29.163034 | L11: 0 | M11: 0.24 | N11: 10.41 | O11: 69.71 | P11: 8.37 | Q11: 2.04 | R11: 8.5 | S11: 0.43 | T11: 0.12 | U11: 0.2 | V11: 0.24
A12: T02 Q3 | B12: c | C12: shell | D12: shell | E12: 0 | F12: 0 | G12: 102962.43 | H12: 535512.73 | I12: -0.335 | J12: -82.997483 | K12: 29.163051 | L12: 0 | M12: 0.22 | N12: 10.5 | O12: 72.84 | P12: 8.74 | Q12: 1.76 | R12: 8 | S12: 0.26 | T12: 0.22 | U12: 0.25 | V12: 0.28
A13: T02 Q4 | B13: c | C13: shell | D13: shell | E13: 0 | F13: 0 | G13: 102964.18 | H13: 535512.66 | I13: -0.393 | J13: -82.997465 | K13: 29.163051 | L13: 0 | M13: 0.21 | N13: 10.04 | O13: 69.45 | P13: 8.33 | Q13: 1.71 | R13: 8.1 | S13: 0.35 | T13: 0.13 | U13: 0.3 | V13: 0.22
A14: T02 Q5 | B14: c | C14: shell | D14: shell | E14: 0 | F14: 0 | G14: 102961.34 | H14: 535512.18 | I14: -0.32 | J14: -82.997494 | K14: 29.163046 | L14: 0 | M14: 0.2 | N14: 10.43 | O14: 74.38 | P14: 8.93 | Q14: 1.5 | R14: 7.5 | S14: 0.21 | T14: 0.15 | U14: 0.42 | V14: 0.22
A15: T03 Q1 | B15: l | C15: jute | D15: shell | E15: 0 | F15: 0 | G15: 102978.99 | H15: 535520.73 | I15: -0.359 | J15: -82.997313 | K15: 29.163125 | L15: 464 | M15: 0.21 | N15: 9.76 | O15: 68.11 | P15: 8.17 | Q15: 1.59 | R15: 7.6 | S15: 0.33 | T15: 0.14 | U15: 0.32 | V15: 0.22
A16: T03 Q2 | B16: l | C16: jute | D16: shell | E16: 0 | F16: 0 | G16: 102971.71 | H16: 535518.62 | I16: -0.35 | J16: -82.997388 | K16: 29.163105 | L16: 464 | M16: 0.22 | N16: 9.51 | O16: 65.13 | P16: 7.82 | Q16: 1.69 | R16: 7.7 | S16: 0.38 | T16: 0.15 | U16: 0.25 | V16: 0.21
A17: T03 Q3 | B17: l | C17: jute | D17: shell | E17: 0 | F17: 0 | G17: 102977.77 | H17: 535520.06 | I17: -0.32 | J17: -82.997326 | K17: 29.163118 | L17: 464 | M17: 0.2 | N17: 9.71 | O17: 72.22 | P17: 8.67 | Q17: 1.04 | R17: 5.2 | S17: 0.29 | T17: 0.15 | U17: 0.37 | V17: 0.19
A18: T03 Q4 | B18: l | C18: jute | D18: jute | E18: 1120 | F18: 100 | G18: 102973.23 | H18: 535517.92 | I18: -0.254 | J18: -82.997372 | K18: 29.163099 | L18: 464
A19: T03 Q5 | B19: l | C19: jute | D19: jute | E19: 1200 | F19: 100 | G19: 102975.12 | H19: 535519.92 | I19: -0.239 | J19: -82.997353 | K19: 29.163117 | L19: 464
A20: T04 Q1 | B20: l | C20: jute | D20: shell | E20: 0 | F20: 0 | G20: 102988.71 | H20: 535522.64 | I20: -0.315 | J20: -82.997213 | K20: 29.163142 | L20: 473.6 | M20: 0.14 | N20: 10.64 | O20: 79.28 | P20: 9.51 | Q20: 1.13 | R20: 8.1 | S20: 0.22 | T20: 0.16 | U20: 0.47 | V20: 0.15
A21: T04 Q2 | B21: l | C21: jute | D21: shell | E21: 0 | F21: 0 | G21: 102989.84 | H21: 535523.17 | I21: -0.284 | J21: -82.997202 | K21: 29.163147 | L21: 473.6 | M21: 0.15 | N21: 10.65 | O21: 79.21 | P21: 9.51 | Q21: 1.14 | R21: 7.6 | S21: 0.29 | T21: 0.23 | U21: 0.33 | V21: 0.14
A22: T04 Q3 | B22: l | C22: jute | D22: jute | E22: 736 | F22: 40 | G22: 102991.46 | H22: 535522.91 | I22: -0.23 | J22: -82.997185 | K22: 29.163145 | L22: 473.6
A23: T04 Q4 | B23: l | C23: jute | D23: jute | E23: 768 | F23: 50 | G23: 102991.99 | H23: 535524.16 | I23: -0.231 | J23: -82.99718 | K23: 29.163156 | L23: 473.6
A24: T04 Q5 | B24: l | C24: jute | D24: jute | E24: 864 | F24: 30 | G24: 102993.08 | H24: 535524.54 | I24: -0.203 | J24: -82.997169 | K24: 29.16316 | L24: 473.6
A25: T05 Q1 | B25: h | C25: jute | D25: shell | E25: 0 | F25: 0 | G25: 103010.43 | H25: 535525.8 | I25: -0.317 | J25: -82.99699 | K25: 29.163173 | L25: 444.8 | M25: 0.14 | N25: 11.12 | O25: 84.25 | P25: 10.11 | Q25: 1.01 | R25: 7.2 | S25: 0.27 | T25: 0.22 | U25: 0.34 | V25: 0.18
A26: T05 Q2 | B26: h | C26: jute | D26: shell | E26: 0 | F26: 0 | G26: 103011.46 | H26: 535527.27 | I26: -0.275 | J26: -82.99698 | K26: 29.163186 | L26: 444.8 | M26: 0.14 | N26: 10.77 | O26: 79.94 | P26: 9.59 | Q26: 1.18 | R26: 8.4 | S26: 0.17 | T26: 0.25 | U26: 0.46 | V26: 0.12
A27: T05 Q3 | B27: h | C27: jute | D27: jute | E27: 704 | F27: 30 | G27: 103005.5 | H27: 535526.05 | I27: -0.175 | J27: -82.997041 | K27: 29.163175 | L27: 444.8
A28: T05 Q4 | B28: h | C28: jute | D28: shell | E28: 0 | F28: 0 | G28: 103003.58 | H28: 535524.43 | I28: -0.318 | J28: -82.997061 | K28: 29.16316 | L28: 444.8 | M28: 0.14 | N28: 10.81 | O28: 80.53 | P28: 9.66 | Q28: 1.15 | R28: 8.2 | S28: 0.3 | T28: 0.18 | U28: 0.36 | V28: 0.16
A29: T05 Q5 | B29: h | C29: jute | D29: jute | E29: 1520 | F29: 80 | G29: 103004.64 | H29: 535524.46 | I29: -0.267 | J29: -82.99705 | K29: 29.16316 | L29: 444.8
A30: T06 Q1 | B30: c | C30: shell | D30: shell | E30: 0 | F30: 0 | G30: 103025.75 | H30: 535530.87 | I30: -0.351 | J30: -82.996833 | K30: 29.16322 | L30: 0 | M30: 0.17 | N30: 10.28 | O30: 72.5 | P30: 8.7 | Q30: 1.58 | R30: 9.3 | S30: 0.3 | T30: 0.12 | U30: 0.37 | V30: 0.21
A31: T06 Q2 | B31: c | C31: shell | D31: shell | E31: 0 | F31: 0 | G31: 103021.1 | H31: 535529.65 | I31: -0.35 | J31: -82.996881 | K31: 29.163208 | L31: 0 | M31: 0.15 | N31: 10.3 | O31: 74.87 | P31: 8.98 | Q31: 1.32 | R31: 8.8 | S31: 0.38 | T31: 0.14 | U31: 0.26 | V31: 0.21
A32: T06 Q3 | B32: c | C32: shell | D32: shell | E32: 0 | F32: 0 | G32: 103022.55 | H32: 535528.72 | I32: -0.405 | J32: -82.996866 | K32: 29.1632 | L32: 0 | M32: 0.13 | N32: 10.69 | O32: 80.07 | P32: 9.61 | Q32: 1.08 | R32: 8.3 | S32: 0.26 | T32: 0.24 | U32: 0.31 | V32: 0.19
A33: T06 Q4 | B33: c | C33: shell | D33: shell | E33: 0 | F33: 0 | G33: 103018.66 | H33: 535528.94 | I33: -0.342 | J33: -82.996906 | K33: 29.163202 | L33: 0 | M33: 0.11 | N33: 10.46 | O33: 79.45 | P33: 9.53 | Q33: 0.93 | R33: 8.5 | S33: 0.25 | T33: 0.2 | U33: 0.39 | V33: 0.16
A34: T06 Q5 | B34: c | C34: shell | D34: shell | E34: 0 | F34: 0 | G34: 103017.62 | H34: 535528.64 | I34: -0.351 | J34: -82.996917 | K34: 29.163199 | L34: 0 | M34: 0.1 | N34: 10.67 | O34: 83 | P34: 9.96 | Q34: 0.71 | R34: 7.1 | S34: 0.25 | T34: 0.21 | U34: 0.41 | V34: 0.13
A35: T07 Q1 | B35: c | C35: shell | D35: shell | E35: 0 | F35: 0 | G35: 103040 | H35: 535532.82 | I35: -0.416 | J35: -82.996687 | K35: 29.163238 | L35: 0 | M35: 0.11 | N35: 10.74 | O35: 80.98 | P35: 9.72 | Q35: 1.02 | R35: 9.3 | S35: 0.22 | T35: 0.2 | U35: 0.44 | V35: 0.14
A36: T07 Q2 | B36: c | C36: shell | D36: shell | E36: 0 | F36: 0 | G36: 103043.53 | H36: 535534.24 | I36: -0.349 | J36: -82.996651 | K36: 29.163251 | L36: 0 | M36: 0.16 | N36: 10.62 | O36: 76.11 | P36: 9.13 | Q36: 1.49 | R36: 9.3 | S36: 0.42 | T36: 0.14 | U36: 0.19 | V36: 0.24
A37: T07 Q3 | B37: c | C37: shell | D37: shell | E37: 0 | F37: 0 | G37: 103037.37 | H37: 535533.67 | I37: -0.33 | J37: -82.996714 | K37: 29.163246 | L37: 0 | M37: 0.16 | N37: 10.59 | O37: 74.87 | P37: 8.98 | Q37: 1.61 | R37: 10.1 | S37: 0.21 | T37: 0.21 | U37: 0.33 | V37: 0.24
A38: T07 Q4 | B38: c | C38: shell | D38: shell | E38: 0 | F38: 0 | G38: 103036.45 | H38: 535532.47 | I38: -0.391 | J38: -82.996723 | K38: 29.163235 | L38: 0 | M38: 0.12 | N38: 10.57 | O38: 78.1 | P38: 9.37 | Q38: 1.2 | R38: 10 | S38: 0.2 | T38: 0.15 | U38: 0.47 | V38: 0.19
A39: T07 Q5 | B39: c | C39: shell | D39: shell | E39: 0 | F39: 0 | G39: 103044.71 | H39: 535534.38 | I39: -0.349 | J39: -82.996639 | K39: 29.163253 | L39: 0 | M39: 0.16 | N39: 10.72 | O39: 76.86 | P39: 9.22 | Q39: 1.5 | R39: 9.4 | S39: 0.31 | T39: 0.14 | U39: 0.33 | V39: 0.22
A40: T08 Q1 | B40: l | C40: jute | D40: jute | E40: 720 | F40: 95 | G40: 103056.14 | H40: 535533.7 | I40: -0.273 | J40: -82.996521 | K40: 29.163247 | L40: 368
A41: T08 Q2 | B41: l | C41: jute | D41: jute | E41: 288 | F41: 15 | G41: 103054.83 | H41: 535535.21 | I41: -0.222 | J41: -82.996535 | K41: 29.163261 | L41: 368
...

Sheet Numeric Summary
A1: Numeric Variable Summary
A2: Descriptive statistics computed live from the Raw Data sheet (formulas, not hardcoded)
A4: Variable | B4: N (non-blank) | C4: Mean | D4: Std Dev | E4: Min | F4: Median | G4: Max | H4: Units / Notes
A5: density (#/m^2) | B5: =COUNT('Raw Data'!E5:E79) -> 75 | C5: =AVERAGE('Raw Data'!E5:E79) -> 355.2 | D5: =STDEV('Raw Data'!E5:E79) -> 564.96946 | E5: =MIN('Raw Data'!E5:E79) -> 0 | F5: =MEDIAN('Raw Data'!E5:E79) -> 0 | G5: =MAX('Raw Data'!E5:E79) -> 2176 | H5: count per quadrat
A6: percent cover | B6: =COUNT('Raw Data'!F5:F79) -> 75 | C6: =AVERAGE('Raw Data'!F5:F79) -> 24.346667 | D6: =STDEV('Raw Data'!F5:F79) -> 38.194203 | E6: =MIN('Raw Data'!F5:F79) -> 0 | F6: =MEDIAN('Raw Data'!F5:F79) -> 0 | G6: =MAX('Raw Data'!F5:F79) -> 100 | H6: %
A7: elevation (m NAVD) | B7: =COUNT('Raw Data'!I5:I79) -> 75 | C7: =AVERAGE('Raw Data'!I5:I79) -> -0.30206667 | D7: =STDEV('Raw Data'!I5:I79) -> 0.060535523 | E7: =MIN('Raw Data'!I5:I79) -> -0.416 | F7: =MEDIAN('Raw Data'!I5:I79) -> -0.308 | G7: =MAX('Raw Data'!I5:I79) -> -0.175 | H7: m, NAVD88 datum
A8: mean oyster density (#/m^2) | B8: =COUNT('Raw Data'!L5:L79) -> 75 | C8: =AVERAGE('Raw Data'!L5:L79) -> 355.2 | D8: =STDEV('Raw Data'!L5:L79) -> 308.95535 | E8: =MIN('Raw Data'!L5:L79) -> 0 | F8: =MEDIAN('Raw Data'!L5:L79) -> 425.6 | G8: =MAX('Raw Data'!L5:L79) -> 1116.8 | H8: site-level mean
A9: wt %N | B9: =COUNT('Raw Data'!M5:M79) -> 51 | C9: =AVERAGE('Raw Data'!M5:M79) -> 0.15745098 | D9: =STDEV('Raw Data'!M5:M79) -> 0.038927786 | E9: =MIN('Raw Data'!M5:M79) -> 0.09 | F9: =MEDIAN('Raw Data'!M5:M79) -> 0.15 | G9: =MAX('Raw Data'!M5:M79) -> 0.26 | H9: sediment, shell samples only
A10: wt %total C | B10: =COUNT('Raw Data'!N5:N79) -> 51 | C10: =AVERAGE('Raw Data'!N5:N79) -> 10.530784 | D10: =STDEV('Raw Data'!N5:N79) -> 0.39941379 | E10: =MIN('Raw Data'!N5:N79) -> 9.51 | F10: =MEDIAN('Raw Data'!N5:N79) -> 10.62 | G10: =MAX('Raw Data'!N5:N79) -> 11.3 | H10: sediment, shell samples only
A11: %CaCO3 | B11: =COUNT('Raw Data'!O5:O79) -> 51 | C11: =AVERAGE('Raw Data'!O5:O79) -> 75.777059 | D11: =STDEV('Raw Data'!O5:O79) -> 4.3173021 | E11: =MIN('Raw Data'!O5:O79) -> 65.13 | F11: =MEDIAN('Raw Data'!O5:O79) -> 76.08 | G11: =MAX('Raw Data'!O5:O79) -> 84.25 | H11: sediment, shell samples only
A12: %TIC | B12: =COUNT('Raw Data'!P5:P79) -> 51 | C12: =AVERAGE('Raw Data'!P5:P79) -> 9.0931373 | D12: =STDEV('Raw Data'!P5:P79) -> 0.51768519 | E12: =MIN('Raw Data'!P5:P79) -> 7.82 | F12: =MEDIAN('Raw Data'!P5:P79) -> 9.13 | G12: =MAX('Raw Data'!P5:P79) -> 10.11 | H12: total inorganic carbon
A13: wt %TOC by difference | B13: =COUNT('Raw Data'!Q5:Q79) -> 51 | C13: =AVERAGE('Raw Data'!Q5:Q79) -> 1.4376471 | D13: =STDEV('Raw Data'!Q5:Q79) -> 0.30137411 | E13: =MIN('Raw Data'!Q5:Q79) -> 0.71 | F13: =MEDIAN('Raw Data'!Q5:Q79) -> 1.46 | G13: =MAX('Raw Data'!Q5:Q79) -> 2.04 | H13: total organic carbon
A14: C:N ratio | B14: =COUNT('Raw Data'!R5:R79) -> 51 | C14: =AVERAGE('Raw Data'!R5:R79) -> 9.3960784 | D14: =STDEV('Raw Data'!R5:R79) -> 2.1014244 | E14: =MIN('Raw Data'!R5:R79) -> 5.2 | F14: =MEDIAN('Raw Data'!R5:R79) -> 9.1 | G14: =MAX('Raw Data'!R5:R79) -> 17.1 | H14: sediment, shell samples only
A15: fraction > 6mm | B15: =COUNT('Raw Data'!S5:S79) -> 51 | C15: =AVERAGE('Raw Data'!S5:S79) -> 0.32098039 | D15: =STDEV('Raw Data'!S5:S79) -> 0.070746163 | E15: =MIN('Raw Data'!S5:S79) -> 0.17 | F15: =MEDIAN('Raw Data'!S5:S79) -> 0.33 | G15: =MAX('Raw Data'!S5:S79) -> 0.44 | H15: grain-size fraction
A16: fraction 2-6mm | B16: =COUNT('Raw Data'!T5:T79) -> 51 | C16: =AVERAGE('Raw Data'!T5:T79) -> 0.17411765 | D16: =STDEV('Raw Data'!T5:T79) -> 0.044729251 | E16: =MIN('Raw Data'!T5:T79) -> 0.09 | F16: =MEDIAN('Raw Data'!T5:T79) -> 0.17 | G16: =MAX('Raw Data'!T5:T79) -> 0.29 | H16: grain-size fraction
A17: fraction .063-2mm | B17: =COUNT('Raw Data'!U5:U79) -> 51 | C17: =AVERAGE('Raw Data'!U5:U79) -> 0.30882353 | D17: =STDEV('Raw Data'!U5:U79) -> 0.074233336 | E17: =MIN('Raw Data'!U5:U79) -> 0.19 | F17: =MEDIAN('Raw Data'!U5:U79) -> 0.3 | G17: =MAX('Raw Data'!U5:U79) -> 0.47 | H17: grain-size fraction
A18: fraction <0.063mm | B18: =COUNT('Raw Data'!V5:V79) -> 51 | C18: =AVERAGE('Raw Data'!V5:V79) -> 0.19588235 | D18: =STDEV('Raw Data'!V5:V79) -> 0.043459244 | E18: =MIN('Raw Data'!V5:V79) -> 0.12 | F18: =MEDIAN('Raw Data'!V5:V79) -> 0.2 | G18: =MAX('Raw Data'!V5:V79) -> 0.31 | H18: grain-size fraction

Sheet By Treatment
A1: Numeric Variable Summary by Treatment
A2: Descriptive statistics computed live from the Raw Data sheet (array formulas, not hardcoded), split by treatment (h/c/l)
A4: Treatment: H (High)
A5: Variable | B5: N (non-blank) | C5: Mean | D5: Std Dev | E5: Min | F5: Median | G5: Max | H5: Units / Notes
A6: density (#/m^2) | B6: =COUNTIFS('Raw Data'!$B$5:$B$79,"h",'Raw Data'!$E$5:$E$79,"<>") -> 25 | C6: =AVERAGEIFS('Raw Data'!$E$5:$E$79,'Raw Data'!$B$5:$B$79,"h") -> 657.28 | D6: {=STDEV(IF('Raw Data'!$B$5:$B$79="h",'Raw Data'!$E$5:$E$79))} -> 738.03949 | E6: =_xlfn.MINIFS('Raw Data'!$E$5:$E$79,'Raw Data'!$B$5:$B$79,"h") -> 0 | F6: {=MEDIAN(IF('Raw Data'!$B$5:$B$79="h",'Raw Data'!$E$5:$E$79))} -> 112 | G6: =_xlfn.MAXIFS('Raw Data'!$E$5:$E$79,'Raw Data'!$B$5:$B$79,"h") -> 2176 | H6: count per quadrat
A7: percent cover | B7: =COUNTIFS('Raw Data'!$B$5:$B$79,"h",'Raw Data'!$F$5:$F$79,"<>") -> 25 | C7: =AVERAGEIFS('Raw Data'!$F$5:$F$79,'Raw Data'!$B$5:$B$79,"h") -> 41.56 | D7: {=STDEV(IF('Raw Data'!$B$5:$B$79="h",'Raw Data'!$F$5:$F$79))} -> 45.916664 | E7: =_xlfn.MINIFS('Raw Data'!$F$5:$F$79,'Raw Data'!$B$5:$B$79,"h") -> 0 | F7: {=MEDIAN(IF('Raw Data'!$B$5:$B$79="h",'Raw Data'!$F$5:$F$79))} -> 2 | G7: =_xlfn.MAXIFS('Raw Data'!$F$5:$F$79,'Raw Data'!$B$5:$B$79,"h") -> 100 | H7: %
A8: elevation (m NAVD) | B8: =COUNTIFS('Raw Data'!$B$5:$B$79,"h",'Raw Data'!$I$5:$I$79,"<>") -> 25 | C8: =AVERAGEIFS('Raw Data'!$I$5:$I$79,'Raw Data'!$B$5:$B$79,"h") -> -0.26488 | D8: {=STDEV(IF('Raw Data'!$B$5:$B$79="h",'Raw Data'!$I$5:$I$79))} -> 0.048623828 | E8: =_xlfn.MINIFS('Raw Data'!$I$5:$I$79,'Raw Data'!$B$5:$B$79,"h") -> -0.346 | F8: {=MEDIAN(IF('Raw Data'!$B$5:$B$79="h",'Raw Data'!$I$5:$I$79))} -> -0.275 | G8: =_xlfn.MAXIFS('Raw Data'!$I$5:$I$79,'Raw Data'!$B$5:$B$79,"h") -> -0.175 | H8: m, NAVD88 datum
A9: mean oyster density (#/m^2) | B9: =COUNTIFS('Raw Data'!$B$5:$B$79,"h",'Raw Data'!$L$5:$L$79,"<>") -> 25 | C9: =AVERAGEIFS('Raw Data'!$L$5:$L$79,'Raw Data'!$B$5:$B$79,"h") -> 657.28 | D9: {=STDEV(IF('Raw Data'!$B$5:$B$79="h",'Raw Data'!$L$5:$L$79))} -> 264.15834 | E9: =_xlfn.MINIFS('Raw Data'!$L$5:$L$79,'Raw Data'!$B$5:$B$79,"h") -> 444.8 | F9: {=MEDIAN(IF('Raw Data'!$B$5:$B$79="h",'Raw Data'!$L$5:$L$79))} -> 492.8 | G9: =_xlfn.MAXIFS('Raw Data'!$L$5:$L$79,'Raw Data'!$B$5:$B$79,"h") -> 1116.8 | H9: site-level mean
A10: wt %N | B10: =COUNTIFS('Raw Data'!$B$5:$B$79,"h",'Raw Data'!$M$5:$M$79,"<>") -> 13 | C10: =AVERAGEIFS('Raw Data'!$M$5:$M$79,'Raw Data'!$B$5:$B$79,"h") -> 0.15923077 | D10: {=STDEV(IF('Raw Data'!$B$5:$B$79="h",'Raw Data'!$M$5:$M$79))} -> 0.08482924 | E10: =_xlfn.MINIFS('Raw Data'!$M$5:$M$79,'Raw Data'!$B$5:$B$79,"h") -> 0.12 | F10: {=MEDIAN(IF('Raw Data'!$B$5:$B$79="h",'Raw Data'!$M$5:$M$79))} -> 0.12 | G10: =_xlfn.MAXIFS('Raw Data'!$M$5:$M$79,'Raw Data'!$B$5:$B$79,"h") -> 0.25 | H10: sediment, shell samples only
A11: wt %total C | B11: =COUNTIFS('Raw Data'!$B$5:$B$79,"h",'Raw Data'!$N$5:$N$79,"<>") -> 13 | C11: =AVERAGEIFS('Raw Data'!$N$5:$N$79,'Raw Data'!$B$5:$B$79,"h") -> 10.648462 | D11: {=STDEV(IF('Raw Data'!$B$5:$B$79="h",'Raw Data'!$N$5:$N$79))} -> 5.4331778 | E11: =_xlfn.MINIFS('Raw Data'!$N$5:$N$79,'Raw Data'!$B$5:$B$79,"h") -> 10.16 | F11: {=MEDIAN(IF('Raw Data'!$B$5:$B$79="h",'Raw Data'!$N$5:$N$79))} -> 10.16 | G11: =_xlfn.MAXIFS('Raw Data'!$N$5:$N$79,'Raw Data'!$B$5:$B$79,"h") -> 11.12 | H11: sediment, shell samples only
A12: %CaCO3 | B12: =COUNTIFS('Raw Data'!$B$5:$B$79,"h",'Raw Data'!$O$5:$O$79,"<>") -> 13 | C12: =AVERAGEIFS('Raw Data'!$O$5:$O$79,'Raw Data'!$B$5:$B$79,"h") -> 77.516154 | D12: {=STDEV(IF('Raw Data'!$B$5:$B$79="h",'Raw Data'!$O$5:$O$79))} -> 39.601195 | E12: =_xlfn.MINIFS('Raw Data'!$O$5:$O$79,'Raw Data'!$B$5:$B$79,"h") -> 72.63 | F12: {=MEDIAN(IF('Raw Data'!$B$5:$B$79="h",'Raw Data'!$O$5:$O$79))} -> 72.63 | G12: =_xlfn.MAXIFS('Raw Data'!$O$5:$O$79,'Raw Data'!$B$5:$B$79,"h") -> 84.25 | H12: sediment, shell samples only
A13: %TIC | B13: =COUNTIFS('Raw Data'!$B$5:$B$79,"h",'Raw Data'!$P$5:$P$79,"<>") -> 13 | C13: =AVERAGEIFS('Raw Data'!$P$5:$P$79,'Raw Data'!$B$5:$B$79,"h") -> 9.3015385 | D13: {=STDEV(IF('Raw Data'!$B$5:$B$79="h",'Raw Data'!$P$5:$P$79))} -> 4.7518924 | E13: =_xlfn.MINIFS('Raw Data'!$P$5:$P$79,'Raw Data'!$B$5:$B$79,"h") -> 8.72 | F13: {=MEDIAN(IF('Raw Data'!$B$5:$B$79="h",'Raw Data'!$P$5:$P$79))} -> 8.72 | G13: =_xlfn.MAXIFS('Raw Data'!$P$5:$P$79,'Raw Data'!$B$5:$B$79,"h") -> 10.11 | H13: total inorganic carbon
A14: wt %TOC by difference | B14: =COUNTIFS('Raw Data'!$B$5:$B$79,"h",'Raw Data'!$Q$5:$Q$79,"<>") -> 13 | C14: =AVERAGEIFS('Raw Data'!$Q$5:$Q$79,'Raw Data'!$B$5:$B$79,"h") -> 1.3469231 | D14: {=STDEV(IF('Raw Data'!$B$5:$B$79="h",'Raw Data'!$Q$5:$Q$79))} -> 0.70097242 | E14: =_xlfn.MINIFS('Raw Data'!$Q$5:$Q$79,'Raw Data'!$B$5:$B$79,"h") -> 1.01 | F14: {=MEDIAN(IF('Raw Data'!$B$5:$B$79="h",'Raw Data'!$Q$5:$Q$79))} -> 1.01 | G14: =_xlfn.MAXIFS('Raw Data'!$Q$5:$Q$79,'Raw Data'!$B$5:$B$79,"h") -> 1.67 | H14: total organic carbon
A15: C:N ratio | B15: =COUNTIFS('Raw Data'!$B$5:$B$79,"h",'Raw Data'!$R$5:$R$79,"<>") -> 13 | C15: =AVERAGEIFS('Raw Data'!$R$5:$R$79,'Raw Data'!$B$5:$B$79,"h") -> 8.6307692 | D15: {=STDEV(IF('Raw Data'!$B$5:$B$79="h",'Raw Data'!$R$5:$R$79))} -> 4.4929871 | E15: =_xlfn.MINIFS('Raw Data'!$R$5:$R$79,'Raw Data'!$B$5:$B$79,"h") -> 6 | F15: {=MEDIAN(IF('Raw Data'!$B$5:$B$79="h",'Raw Data'!$R$5:$R$79))} -> 6 | G15: =_xlfn.MAXIFS('Raw Data'!$R$5:$R$79,'Raw Data'!$B$5:$B$79,"h") -> 10.2 | H15: sediment, shell samples only
A16: fraction > 6mm | B16: =COUNTIFS('Raw Data'!$B$5:$B$79,"h",'Raw Data'!$S$5:$S$79,"<>") -> 13 | C16: =AVERAGEIFS('Raw Data'!$S$5:$S$79,'Raw Data'!$B$5:$B$79,"h") -> 0.32153846 | D16: {=STDEV(IF('Raw Data'!$B$5:$B$79="h",'Raw Data'!$S$5:$S$79))} -> 0.17213173 | E16: =_xlfn.MINIFS('Raw Data'!$S$5:$S$79,'Raw Data'!$B$5:$B$79,"h") -> 0.17 | F16: {=MEDIAN(IF('Raw Data'!$B$5:$B$79="h",'Raw Data'!$S$5:$S$79))} -> 0.17 | G16: =_xlfn.MAXIFS('Raw Data'!$S$5:$S$79,'Raw Data'!$B$5:$B$79,"h") -> 0.44 | H16: grain-size fraction
A17: fraction 2-6mm | B17: =COUNTIFS('Raw Data'!$B$5:$B$79,"h",'Raw Data'!$T$5:$T$79,"<>") -> 13 | C17: =AVERAGEIFS('Raw Data'!$T$5:$T$79,'Raw Data'!$B$5:$B$79,"h") -> 0.19846154 | D17: {=STDEV(IF('Raw Data'!$B$5:$B$79="h",'Raw Data'!$T$5:$T$79))} -> 0.10648631 | E17: =_xlfn.MINIFS('Raw Data'!$T$5:$T$79,'Raw Data'!$B$5:$B$79,"h") -> 0.13 | F17: {=MEDIAN(IF('Raw Data'!$B$5:$B$79="h",'Raw Data'!$T$5:$T$79))} -> 0.13 | G17: =_xlfn.MAXIFS('Raw Data'!$T$5:$T$79,'Raw Data'!$B$5:$B$79,"h") -> 0.29 | H17: grain-size fraction
A18: fraction .063-2mm | B18: =COUNTIFS('Raw Data'!$B$5:$B$79,"h",'Raw Data'!$U$5:$U$79,"<>") -> 13 | C18: =AVERAGEIFS('Raw Data'!$U$5:$U$79,'Raw Data'!$B$5:$B$79,"h") -> 0.31153846 | D18: {=STDEV(IF('Raw Data'!$B$5:$B$79="h",'Raw Data'!$U$5:$U$79))} -> 0.16827557 | E18: =_xlfn.MINIFS('Raw Data'!$U$5:$U$79,'Raw Data'!$B$5:$B$79,"h") -> 0.22 | F18: {=MEDIAN(IF('Raw Data'!$B$5:$B$79="h",'Raw Data'!$U$5:$U$79))} -> 0.22 | G18: =_xlfn.MAXIFS('Raw Data'!$U$5:$U$79,'Raw Data'!$B$5:$B$79,"h") -> 0.46 | H18: grain-size fraction
A19: fraction <0.063mm | B19: =COUNTIFS('Raw Data'!$B$5:$B$79,"h",'Raw Data'!$V$5:$V$79,"<>") -> 13 | C19: =AVERAGEIFS('Raw Data'!$V$5:$V$79,'Raw Data'!$B$5:$B$79,"h") -> 0.16846154 | D19: {=STDEV(IF('Raw Data'!$B$5:$B$79="h",'Raw Data'!$V$5:$V$79))} -> 0.088613393 | E19: =_xlfn.MINIFS('Raw Data'!$V$5:$V$79,'Raw Data'!$B$5:$B$79,"h") -> 0.12 | F19: {=MEDIAN(IF('Raw Data'!$B$5:$B$79="h",'Raw Data'!$V$5:$V$79))} -> 0.12 | G19: =_xlfn.MAXIFS('Raw Data'!$V$5:$V$79,'Raw Data'!$B$5:$B$79,"h") -> 0.23 | H19: grain-size fraction
A21: Treatment: C (Control)
A22: Variable | B22: N (non-blank) | C22: Mean | D22: Std Dev | E22: Min | F22: Median | G22: Max | H22: Units / Notes
A23: density (#/m^2) | B23: =COUNTIFS('Raw Data'!$B$5:$B$79,"c",'Raw Data'!$E$5:$E$79,"<>") -> 25 | C23: =AVERAGEIFS('Raw Data'!$E$5:$E$79,'Raw Data'!$B$5:$B$79,"c") -> 44.16 | D23: {=STDEV(IF('Raw Data'!$B$5:$B$79="c",'Raw Data'!$E$5:$E$79))} -> 214.22879 | E23: =_xlfn.MINIFS('Raw Data'!$E$5:$E$79,'Raw Data'!$B$5:$B$79,"c") -> 0 | F23: {=MEDIAN(IF('Raw Data'!$B$5:$B$79="c",'Raw Data'!$E$5:$E$79))} -> 0 | G23: =_xlfn.MAXIFS('Raw Data'!$E$5:$E$79,'Raw Data'!$B$5:$B$79,"c") -> 1072 | H23: count per quadrat
A24: percent cover | B24: =COUNTIFS('Raw Data'!$B$5:$B$79,"c",'Raw Data'!$F$5:$F$79,"<>") -> 25 | C24: =AVERAGEIFS('Raw Data'!$F$5:$F$79,'Raw Data'!$B$5:$B$79,"c") -> 2.84 | D24: {=STDEV(IF('Raw Data'!$B$5:$B$79="c",'Raw Data'!$F$5:$F$79))} -> 13.993094 | E24: =_xlfn.MINIFS('Raw Data'!$F$5:$F$79,'Raw Data'!$B$5:$B$79,"c") -> 0 | F24: {=MEDIAN(IF('Raw Data'!$B$5:$B$79="c",'Raw Data'!$F$5:$F$79))} -> 0 | G24: =_xlfn.MAXIFS('Raw Data'!$F$5:$F$79,'Raw Data'!$B$5:$B$79,"c") -> 70 | H24: %
A25: elevation (m NAVD) | B25: =COUNTIFS('Raw Data'!$B$5:$B$79,"c",'Raw Data'!$I$5:$I$79,"<>") -> 25 | C25: =AVERAGEIFS('Raw Data'!$I$5:$I$79,'Raw Data'!$B$5:$B$79,"c") -> -0.35724 | D25: {=STDEV(IF('Raw Data'!$B$5:$B$79="c",'Raw Data'!$I$5:$I$79))} -> 0.033591021 | E25: =_xlfn.MINIFS('Raw Data'!$I$5:$I$79,'Raw Data'!$B$5:$B$79,"c") -> -0.416 | F25: {=MEDIAN(IF('Raw Data'!$B$5:$B$79="c",'Raw Data'!$I$5:$I$79))} -> -0.351 | G25: =_xlfn.MAXIFS('Raw Data'!$I$5:$I$79,'Raw Data'!$B$5:$B$79,"c") -> -0.289 | H25: m, NAVD88 datum
A26: mean oyster density (#/m^2) | B26: =COUNTIFS('Raw Data'!$B$5:$B$79,"c",'Raw Data'!$L$5:$L$79,"<>") -> 25 | C26: =AVERAGEIFS('Raw Data'!$L$5:$L$79,'Raw Data'!$B$5:$B$79,"c") -> 44.16 | D26: {=STDEV(IF('Raw Data'!$B$5:$B$79="c",'Raw Data'!$L$5:$L$79))} -> 86.912063 | E26: =_xlfn.MINIFS('Raw Data'!$L$5:$L$79,'Raw Data'!$B$5:$B$79,"c") -> 0 | F26: {=MEDIAN(IF('Raw Data'!$B$5:$B$79="c",'Raw Data'!$L$5:$L$79))} -> 0 | G26: =_xlfn.MAXIFS('Raw Data'!$L$5:$L$79,'Raw Data'!$B$5:$B$79,"c") -> 214.4 | H26: site-level mean
A27: wt %N | B27: =COUNTIFS('Raw Data'!$B$5:$B$79,"c",'Raw Data'!$M$5:$M$79,"<>") -> 25 | C27: =AVERAGEIFS('Raw Data'!$M$5:$M$79,'Raw Data'!$B$5:$B$79,"c") -> 0.16 | D27: {=STDEV(IF('Raw Data'!$B$5:$B$79="c",'Raw Data'!$M$5:$M$79))} -> 0.042817442 | E27: =_xlfn.MINIFS('Raw Data'!$M$5:$M$79,'Raw Data'!$B$5:$B$79,"c") -> 0.09 | F27: {=MEDIAN(IF('Raw Data'!$B$5:$B$79="c",'Raw Data'!$M$5:$M$79))} -> 0.16 | G27: =_xlfn.MAXIFS('Raw Data'!$M$5:$M$79,'Raw Data'!$B$5:$B$79,"c") -> 0.26 | H27: sediment, shell samples only
A28: wt %total C | B28: =COUNTIFS('Raw Data'!$B$5:$B$79,"c",'Raw Data'!$N$5:$N$79,"<>") -> 25 | C28: =AVERAGEIFS('Raw Data'!$N$5:$N$79,'Raw Data'!$B$5:$B$79,"c") -> 10.5416 | D28: {=STDEV(IF('Raw Data'!$B$5:$B$79="c",'Raw Data'!$N$5:$N$79))} -> 0.27667189 | E28: =_xlfn.MINIFS('Raw Data'!$N$5:$N$79,'Raw Data'!$B$5:$B$79,"c") -> 9.97 | F28: {=MEDIAN(IF('Raw Data'!$B$5:$B$79="c",'Raw Data'!$N$5:$N$79))} -> 10.59 | G28: =_xlfn.MAXIFS('Raw Data'!$N$5:$N$79,'Raw Data'!$B$5:$B$79,"c") -> 11.14 | H28: sediment, shell samples only
A29: %CaCO3 | B29: =COUNTIFS('Raw Data'!$B$5:$B$79,"c",'Raw Data'!$O$5:$O$79,"<>") -> 25 | C29: =AVERAGEIFS('Raw Data'!$O$5:$O$79,'Raw Data'!$B$5:$B$79,"c") -> 75.0624 | D29: {=STDEV(IF('Raw Data'!$B$5:$B$79="c",'Raw Data'!$O$5:$O$79))} -> 4.0600116 | E29: =_xlfn.MINIFS('Raw Data'!$O$5:$O$79,'Raw Data'!$B$5:$B$79,"c") -> 68.11 | F29: {=MEDIAN(IF('Raw Data'!$B$5:$B$79="c",'Raw Data'!$O$5:$O$79))} -> 74.87 | G29: =_xlfn.MAXIFS('Raw Data'!$O$5:$O$79,'Raw Data'!$B$5:$B$79,"c") -> 83 | H29: sediment, shell samples only
A30: %TIC | B30: =COUNTIFS('Raw Data'!$B$5:$B$79,"c",'Raw Data'!$P$5:$P$79,"<>") -> 25 | C30: =AVERAGEIFS('Raw Data'!$P$5:$P$79,'Raw Data'!$B$5:$B$79,"c") -> 9.0072 | D30: {=STDEV(IF('Raw Data'!$B$5:$B$79="c",'Raw Data'!$P$5:$P$79))} -> 0.4869336 | E30: =_xlfn.MINIFS('Raw Data'!$P$5:$P$79,'Raw Data'!$B$5:$B$79,"c") -> 8.17 | F30: {=MEDIAN(IF('Raw Data'!$B$5:$B$79="c",'Raw Data'!$P$5:$P$79))} -> 8.98 | G30: =_xlfn.MAXIFS('Raw Data'!$P$5:$P$79,'Raw Data'!$B$5:$B$79,"c") -> 9.96 | H30: total inorganic carbon
A31: wt %TOC by difference | B31: =COUNTIFS('Raw Data'!$B$5:$B$79,"c",'Raw Data'!$Q$5:$Q$79,"<>") -> 25 | C31: =AVERAGEIFS('Raw Data'!$Q$5:$Q$79,'Raw Data'!$B$5:$B$79,"c") -> 1.5344 | D31: {=STDEV(IF('Raw Data'!$B$5:$B$79="c",'Raw Data'!$Q$5:$Q$79))} -> 0.34328171 | E31: =_xlfn.MINIFS('Raw Data'!$Q$5:$Q$79,'Raw Data'!$B$5:$B$79,"c") -> 0.71 | F31: {=MEDIAN(IF('Raw Data'!$B$5:$B$79="c",'Raw Data'!$Q$5:$Q$79))} -> 1.54 | G31: =_xlfn.MAXIFS('Raw Data'!$Q$5:$Q$79,'Raw Data'!$B$5:$B$79,"c") -> 2.04 | H31: total organic carbon
A32: C:N ratio | B32: =COUNTIFS('Raw Data'!$B$5:$B$79,"c",'Raw Data'!$R$5:$R$79,"<>") -> 25 | C32: =AVERAGEIFS('Raw Data'!$R$5:$R$79,'Raw Data'!$B$5:$B$79,"c") -> 9.836 | D32: {=STDEV(IF('Raw Data'!$B$5:$B$79="c",'Raw Data'!$R$5:$R$79))} -> 2.1422107 | E32: =_xlfn.MINIFS('Raw Data'!$R$5:$R$79,'Raw Data'!$B$5:$B$79,"c") -> 7.1 | F32: {=MEDIAN(IF('Raw Data'!$B$5:$B$79="c",'Raw Data'!$R$5:$R$79))} -> 9.3 | G32: =_xlfn.MAXIFS('Raw Data'!$R$5:$R$79,'Raw Data'!$B$5:$B$79,"c") -> 17.1 | H32: sediment, shell samples only
A33: fraction > 6mm | B33: =COUNTIFS('Raw Data'!$B$5:$B$79,"c",'Raw Data'!$S$5:$S$79,"<>") -> 25 | C33: =AVERAGEIFS('Raw Data'!$S$5:$S$79,'Raw Data'!$B$5:$B$79,"c") -> 0.326 | D33: {=STDEV(IF('Raw Data'!$B$5:$B$79="c",'Raw Data'!$S$5:$S$79))} -> 0.075773786 | E33: =_xlfn.MINIFS('Raw Data'!$S$5:$S$79,'Raw Data'!$B$5:$B$79,"c") -> 0.2 | F33: {=MEDIAN(IF('Raw Data'!$B$5:$B$79="c",'Raw Data'!$S$5:$S$79))} -> 0.34 | G33: =_xlfn.MAXIFS('Raw Data'!$S$5:$S$79,'Raw Data'!$B$5:$B$79,"c") -> 0.44 | H33: grain-size fraction
A34: fraction 2-6mm | B34: =COUNTIFS('Raw Data'!$B$5:$B$79,"c",'Raw Data'!$T$5:$T$79,"<>") -> 25 | C34: =AVERAGEIFS('Raw Data'!$T$5:$T$79,'Raw Data'!$B$5:$B$79,"c") -> 0.1572 | D34: {=STDEV(IF('Raw Data'!$B$5:$B$79="c",'Raw Data'!$T$5:$T$79))} -> 0.041384377 | E34: =_xlfn.MINIFS('Raw Data'!$T$5:$T$79,'Raw Data'!$B$5:$B$79,"c") -> 0.09 | F34: {=MEDIAN(IF('Raw Data'!$B$5:$B$79="c",'Raw Data'!$T$5:$T$79))} -> 0.14 | G34: =_xlfn.MAXIFS('Raw Data'!$T$5:$T$79,'Raw Data'!$B$5:$B$79,"c") -> 0.24 | H34: grain-size fraction
A35: fraction .063-2mm | B35: =COUNTIFS('Raw Data'!$B$5:$B$79,"c",'Raw Data'!$U$5:$U$79,"<>") -> 25 | C35: =AVERAGEIFS('Raw Data'!$U$5:$U$79,'Raw Data'!$B$5:$B$79,"c") -> 0.2996 | D35: {=STDEV(IF('Raw Data'!$B$5:$B$79="c",'Raw Data'!$U$5:$U$79))} -> 0.078606615 | E35: =_xlfn.MINIFS('Raw Data'!$U$5:$U$79,'Raw Data'!$B$5:$B$79,"c") -> 0.19 | F35: {=MEDIAN(IF('Raw Data'!$B$5:$B$79="c",'Raw Data'!$U$5:$U$79))} -> 0.28 | G35: =_xlfn.MAXIFS('Raw Data'!$U$5:$U$79,'Raw Data'!$B$5:$B$79,"c") -> 0.47 | H35: grain-size fraction
A36: fraction <0.063mm | B36: =COUNTIFS('Raw Data'!$B$5:$B$79,"c",'Raw Data'!$V$5:$V$79,"<>") -> 25 | C36: =AVERAGEIFS('Raw Data'!$V$5:$V$79,'Raw Data'!$B$5:$B$79,"c") -> 0.2172 | D36: {=STDEV(IF('Raw Data'!$B$5:$B$79="c",'Raw Data'!$V$5:$V$79))} -> 0.042673177 | E36: =_xlfn.MINIFS('Raw Data'!$V$5:$V$79,'Raw Data'!$B$5:$B$79,"c") -> 0.13 | F36: {=MEDIAN(IF('Raw Data'!$B$5:$B$79="c",'Raw Data'!$V$5:$V$79))} -> 0.22 | G36: =_xlfn.MAXIFS('Raw Data'!$V$5:$V$79,'Raw Data'!$B$5:$B$79,"c") -> 0.31 | H36: grain-size fraction
A38: Treatment: L (Low)
A39: Variable | B39: N (non-blank) | C39: Mean | D39: Std Dev | E39: Min | F39: Median | G39: Max | H39: Units / Notes
A40: density (#/m^2) | B40: =COUNTIFS('Raw Data'!$B$5:$B$79,"l",'Raw Data'!$E$5:$E$79,"<>") -> 25 | C40: =AVERAGEIFS('Raw Data'!$E$5:$E$79,'Raw Data'!$B$5:$B$79,"l") -> 364.16 | D40: {=STDEV(IF('Raw Data'!$B$5:$B$79="l",'Raw Data'!$E$5:$E$79))} -> 444.58892 | E40: =_xlfn.MINIFS('Raw Data'!$E$5:$E$79,'Raw Data'!$B$5:$B$79,"l") -> 0 | F40: {=MEDIAN(IF('Raw Data'!$B$5:$B$79="l",'Raw Data'!$E$5:$E$79))} -> 16 | G40: =_xlfn.MAXIFS('Raw Data'!$E$5:$E$79,'Raw Data'!$B$5:$B$79,"l") -> 1200 | H40: count per quadrat
A41: percent cover | B41: =COUNTIFS('Raw Data'!$B$5:$B$79,"l",'Raw Data'!$F$5:$F$79,"<>") -> 25 | C41: =AVERAGEIFS('Raw Data'!$F$5:$F$79,'Raw Data'!$B$5:$B$79,"l") -> 28.64 | D41: {=STDEV(IF('Raw Data'!$B$5:$B$79="l",'Raw Data'!$F$5:$F$79))} -> 37.204256 | E41: =_xlfn.MINIFS('Raw Data'!$F$5:$F$79,'Raw Data'!$B$5:$B$79,"l") -> 0 | F41: {=MEDIAN(IF('Raw Data'!$B$5:$B$79="l",'Raw Data'!$F$5:$F$79))} -> 1 | G41: =_xlfn.MAXIFS('Raw Data'!$F$5:$F$79,'Raw Data'!$B$5:$B$79,"l") -> 100 | H41: %
A42: elevation (m NAVD) | B42: =COUNTIFS('Raw Data'!$B$5:$B$79,"l",'Raw Data'!$I$5:$I$79,"<>") -> 25 | C42: =AVERAGEIFS('Raw Data'!$I$5:$I$79,'Raw Data'!$B$5:$B$79,"l") -> -0.28408 | D42: {=STDEV(IF('Raw Data'!$B$5:$B$79="l",'Raw Data'!$I$5:$I$79))} -> 0.053460203 | E42: =_xlfn.MINIFS('Raw Data'!$I$5:$I$79,'Raw Data'!$B$5:$B$79,"l") -> -0.39 | F42: {=MEDIAN(IF('Raw Data'!$B$5:$B$79="l",'Raw Data'!$I$5:$I$79))} -> -0.28 | G42: =_xlfn.MAXIFS('Raw Data'!$I$5:$I$79,'Raw Data'!$B$5:$B$79,"l") -> -0.196 | H42: m, NAVD88 datum
A43: mean oyster density (#/m^2) | B43: =COUNTIFS('Raw Data'!$B$5:$B$79,"l",'Raw Data'!$L$5:$L$79,"<>") -> 25 | C43: =AVERAGEIFS('Raw Data'!$L$5:$L$79,'Raw Data'!$B$5:$B$79,"l") -> 364.16 | D43: {=STDEV(IF('Raw Data'!$B$5:$B$79="l",'Raw Data'!$L$5:$L$79))} -> 145.14214 | E43: =_xlfn.MINIFS('Raw Data'!$L$5:$L$79,'Raw Data'!$B$5:$B$79,"l") -> 89.6 | F43: {=MEDIAN(IF('Raw Data'!$B$5:$B$79="l",'Raw Data'!$L$5:$L$79))} -> 425.6 | G43: =_xlfn.MAXIFS('Raw Data'!$L$5:$L$79,'Raw Data'!$B$5:$B$79,"l") -> 473.6 | H43: site-level mean
...

Sheet Categorical Summary
A1: Categorical Variable Summary
A2: Counts computed live from the Raw Data sheet (COUNTIF formulas)
A4: treatment
A5: Level | B5: Count | C5: % of 75 samples | D5: Note
A6: h | B6: =COUNTIF('Raw Data'!B5:B79,"h") -> 25 | C6: =B6/75 -> 0.33333333 | D6: high (treatment level)
A7: c | B7: =COUNTIF('Raw Data'!B5:B79,"c") -> 25 | C7: =B7/75 -> 0.33333333 | D7: control
A8: l | B8: =COUNTIF('Raw Data'!B5:B79,"l") -> 25 | C8: =B8/75 -> 0.33333333 | D8: low (treatment level)
A10: treatment substrate
A11: Level | B11: Count | C11: % of 75 samples | D11: Note
A12: jute | B12: =COUNTIF('Raw Data'!C5:C79,"jute") -> 50 | C12: =B12/75 -> 0.66666667
A13: shell | B13: =COUNTIF('Raw Data'!C5:C79,"shell") -> 25 | C13: =B13/75 -> 0.33333333
A15: substrate sampled
A16: Level | B16: Count | C16: % of 75 samples | D16: Note
A17: jute | B17: =COUNTIF('Raw Data'!D5:D79,"jute") -> 24 | C17: =B17/75 -> 0.32
A18: shell | B18: =COUNTIF('Raw Data'!D5:D79,"shell") -> 51 | C18: =B18/75 -> 0.68

Sheet Notes
A1: Notes on the Data
A3: • Dataset: oyster reef restoration monitoring — 75 quadrat samples at a single field site (~29.163°N, -82.997°W), comparing three treatments (h/high, c/control, l/low) and two substrate types (jute vs. shell).
A5: • Sediment / elemental columns (wt %N, wt %total C, %CaCO3, %TIC, wt %TOC by difference, C:N ratio, and the four grain-size fraction columns) are populated for 51 of 75 rows. The 24 missing rows all have 'substrate sampled' = jute — these analyses were only run on shell-substrate samples.
A7: • 'treatment substrate' records what substrate was deployed as part of the experimental design; 'substrate sampled' records what was actually collected at that quadrat, and the two do not always match.
A9: • Coordinates are supplied in two systems: projected easting/northing and geographic longitude/latitude (both referencing the same locations).
A11: • 'mean oyster density' appears to be a site- or treatment-level average rather than a per-quadrat count, since it repeats across multiple rows sharing similar coordinates.
